<?xml version="1.0"?>
<robot name="spacerobot">
    <!-- Materials -->
    <material name="blue">
        <color rgba="0 0 0.8 1"/>
    </material>
    <material name="silver">
        <color rgba="0.75 0.75 0.75 1"/>
    </material>
    
    
    <link name="chasersat">
        <visual>
            <geometry>
                <box size="0.6 1.2 0.6"/>
            </geometry>
            <material name="silver"/>
        </visual>
        <collision>
            <geometry>
                <box size="0.6 1.2 0.6"/>
            </geometry>
        </collision>
        <inertial>
            <mass value="419.8441"/>
            <inertia ixx="83.97" ixy="0" ixz="0" iyy="83.97" iyz="0" izz="83.97"/>
        </inertial>
    </link>
    <!-- Shoulder link -->
    <joint name="shoulder_pan_joint" type="revolute">
        <parent link="chasersat"/>
        <child link="shoulder_link"/>
        <origin xyz="0.11855 -0.4 0.29550" rpy="0 0 0"/>
        <axis xyz="0 0 1"/>
        <limit lower="-3.14" upper="3.14" effort="150" velocity="3.14"/>
        <dynamics damping="1" friction="0"/>
    </joint>
    
    <link name="shoulder_link">
        <visual>
            <geometry>
                <mesh filename="/stls/legacy/shaft.stl" scale="1 1 1"/>
            </geometry>
            <origin xyz="0 0 0" rpy="0 0 0"/>
            <material name="blue"/>
        </visual>
        <collision>
            <geometry>
                <cylinder radius="0.08" length="0.277"/>
            </geometry>
            <origin xyz="0 0.1385 0" rpy="1.57 0 0"/>
        </collision>
        <inertial>
            <mass value="3.7"/>
            <origin xyz="-0.064465 0 0" rpy="0 0 0"/>
            <inertia ixx="0.0067" ixy="0" ixz="0" iyy="0.0064" iyz="0" izz="0.0067"/>
        </inertial>
    </link>
    
    <!-- Upper arm link -->
    <joint name="shoulder_lift_joint" type="revolute">
        <parent link="shoulder_link"/>
        <child link="upper_arm_link"/>
        <origin xyz="0 0.277 0" rpy="-1.57 0 3.14"/>
        <axis xyz="0 0 1"/>
        <limit lower="-3.14" upper="3.14" effort="150" velocity="3.14"/>
        <dynamics damping="1" friction="0"/>
    </joint>
    
    <link name="upper_arm_link">
        <visual>
            <geometry>
                <mesh filename="/stls/legacy/link2.stl" scale="1 1 1"/>
            </geometry>
            <origin xyz="0.064 0 0" rpy="0 -1.57 0"/>
            <material name="blue"/>
        </visual>
        <visual>
            <geometry>
                <mesh filename="/stls/legacy/shaft.stl" scale="1 1 1"/>
            </geometry>
            <origin xyz="-0.145 0 0" rpy="0 -1.57 0"/>
            <material name="blue"/>
        </visual>
        <collision>
            <geometry>
                <cylinder radius="0.08" length="0.55"/>
            </geometry>
            <origin xyz="-0.275 0 0" rpy="0 1.57 0"/>
        </collision>
        <inertial>
            <mass value="1.0"/>
            <inertia ixx="1" ixy="0" ixz="0" iyy="1" iyz="0" izz="1"/>
        </inertial>
    </link>
    
    <!-- Forearm link -->
    <joint name="elbow_joint" type="revolute">
        <parent link="upper_arm_link"/>
        <child link="forearm_link"/>
        <origin xyz="-0.55 0 0" rpy="1.57 -1.57 0"/>
        <axis xyz="0 0 1"/>
        <limit lower="-3.14" upper="3.14" effort="150" velocity="3.14"/>
        <dynamics damping="1" friction="0"/>
    </joint>
    
    <link name="forearm_link">
        <visual>
            <geometry>
                <mesh filename="/stls/legacy/link2.stl" scale="1 1 1"/>
            </geometry>
            <origin xyz="0 0 0.032" rpy="3.14 0 0"/>
            <material name="blue"/>
        </visual>
        <visual>
            <geometry>
                <mesh filename="/stls/legacy/shaft2.stl" scale="1 1 1"/>
            </geometry>
            <origin xyz="-0.0906 0 -0.032" rpy="0 1.57 0"/>
            <material name="blue"/>
        </visual>
        <collision>
            <geometry>
                <cylinder radius="0.07" length="0.39"/>
            </geometry>
            <origin xyz="-0.081 0 0.195" rpy="1.57 0 0"/>
        </collision>
        <inertial>
            <mass value="2.275"/>
            <origin xyz="0.11993 0 0.0265" rpy="0 0 0"/>
            <inertia ixx="0.0025" ixy="0" ixz="0" iyy="0.0551" iyz="0" izz="0.0546"/>
        </inertial>
    </link>
    
    <!-- Wrist 1 link -->
    <joint name="wrist_1_joint" type="revolute">
        <parent link="forearm_link"/>
        <child link="wrist_1_link"/>
        <origin xyz="-0.162 0 0.390" rpy="0 -1.5707963 -1.5707963"/>
        <axis xyz="0 0 1"/>
        <limit lower="-3.14" upper="3.14" effort="28" velocity="3.14"/>
        <dynamics damping="1" friction="0"/>
    </joint>
    
    <link name="wrist_1_link">
        <visual>
            <geometry>
                <mesh filename="/stls/legacy/link3.stl" scale="1 1 1"/>
            </geometry>
            <origin xyz="0 -0.478 -0.025" rpy="-1.57 0 -1.57"/>
            <material name="blue"/>
        </visual>
        <visual>
            <geometry>
                <mesh filename="/stls/legacy/shaft2.stl" scale="1 1 1"/>
            </geometry>
            <origin xyz="0.039 0 -0.025" rpy="0 1.57 0"/>
            <material name="blue"/>
        </visual>
        <collision>
            <geometry>
                <cylinder radius="0.06" length="0.16"/>
            </geometry>
            <origin xyz="0.08 0.185 0" rpy="1.57 0 0"/>
        </collision>
        <inertial>
            <mass value="1.0"/>
            <inertia ixx="1" ixy="0" ixz="0" iyy="1" iyz="0" izz="1"/>
        </inertial>
    </link>
    
    <!-- Wrist 2 link -->
    <joint name="wrist_2_joint" type="revolute">
        <parent link="wrist_1_link"/>
        <child link="wrist_2_link"/>
        <origin xyz="0.160 0.370 0" rpy="1.5707963 1.5707963 0"/>
        <axis xyz="0 0 1"/>
        <limit lower="-3.14" upper="3.14" effort="28" velocity="3.14"/>
        <dynamics damping="1" friction="0"/>
    </joint>
    
    <link name="wrist_2_link">
        <visual>
            <geometry>
                <mesh filename="/stls/legacy/link4.stl" scale="1 1 1"/>
            </geometry>
            <origin xyz="0 0 0" rpy="0 0 0"/>
            <material name="blue"/>
        </visual>
        <visual>
            <geometry>
                <mesh filename="/stls/legacy/shaft2.stl" scale="1 1 1"/>
            </geometry>
            <origin xyz="0 0 -0.0385" rpy="0 0 0"/>
            <material name="blue"/>
        </visual>
        <collision>
            <geometry>
                <cylinder radius="0.06" length="0.305"/>
            </geometry>
            <origin xyz="0.1525 0 -0.08" rpy="1.57 0 0"/>
        </collision>
        <inertial>
            <mass value="1.0"/>
            <origin xyz="0 0.0018 0.01634" rpy="0 0 0"/>
            <inertia ixx="0.0012" ixy="0" ixz="0" iyy="0.0012" iyz="0" izz="0.0009"/>
        </inertial>
    </link>
    
    <!-- Wrist 3 link -->
    <joint name="wrist_3_joint" type="revolute">
        <parent link="wrist_2_link"/>
        <child link="wrist_3_link"/>
        <origin xyz="0.305 0 -0.160" rpy="0 0 0"/>
        <axis xyz="0 0 1"/>
        <limit lower="-3.14" upper="3.14" effort="28" velocity="3.14"/>
        <dynamics damping="1" friction="0"/>
    </joint>
    
    <link name="wrist_3_link">
        <visual>
            <geometry>
                <mesh filename="/stls/legacy/link5.stl" scale="1 1 1"/>
            </geometry>
            <origin xyz="0 0 0" rpy="-1.57 0 0"/>
            <material name="blue"/>
        </visual>
        <collision>
            <geometry>
                <sphere radius="0.05"/>
            </geometry>
            <origin xyz="0 0 0" rpy="0 0 0"/>
        </collision>
        <inertial>
            <mass value="1.0"/>
            <origin xyz="0 0 -0.01159" rpy="0 0 0"/>
            <inertia ixx="0.0000884489143" ixy="0" ixz="0" iyy="0.0000884489143" iyz="0" izz="0.000138534912"/>
        </inertial>
    </link>
    

