<?xml version="1.0"?>
<mujoco model="spacerobot">
    <compiler angle="radian" coordinate="local" eulerseq="xyz" />
    <option cone="elliptic" gravity="0 0 0" impratio="5" timestep="0.01" tolerance="1e-10" />
    <default class="main">
        <joint damping="0" armature="1" />
        <geom condim="4" solimp="0.99 0.99 0.01" solref="0.01 1" />
        <default class="arm1">
            <joint damping="0" />
        </default>
        <default class="arm2">
            <joint damping="0" />
        </default>
    </default>

    <include file="common/visual.xml" />
    <include file="common/skybox.xml" />
    <include file="common/materials.xml" />

    <include file="asset_legacy.xml" />

    <worldbody>
        <camera mode="targetbody" name="cam_to_dockingring" pos="0 0 0" target="chasersat" />
        <light dir="0 0 -1" directional="true" name="light1" pos="0 -1 6" />
        <light dir="0 0 -1" directional="true" name="light2" pos="0 1 6" />

        <body name="chasersat" pos="0.2 1.3 0" euler="0 1.57 0"> <!-- 0 1.165 0-->
            <freejoint name="chasersat:joint" />
            <geom name="chasersat" mass="419.8441" pos="0 0 0"  size="0.3 0.6 0.3" type="box" />
            <body name="chasersat_base" pos="0.11855 -0.4 0.29550">
                <body name="base_link" pos="0 0 0" euler="0 0 -1.57">
                    <body name="shoulder_link" pos="0 0 0.240" euler="0 0 0 ">
                    <geom name="v_base_link" pos=" 0 0 -0.240" type="mesh" group="1" mesh="shaft_base" euler="1.57 1.57 0" />
                    <geom name="v_shoulder_link" type="mesh" group="1" mesh="shaft1" euler="-1.57 0 0" />
                    <inertial pos="-0.064465 0 0" mass="3.7" diaginertia="0.0067 0.0064 0.0067" />
                        <joint class="arm1" name="arm:shoulder_pan_joint" axis="0 0 1" pos="0 -0.02561 0" />
                        <body name="upper_arm_link" pos="0 0.277 0" euler="-1.57 0 3.14">
                        <inertial pos="0.0 0 0.0" mass="1" diaginertia="1 1 1" />
                        <joint class="arm1" name="arm:shoulder_lift_joint" axis="0 0 1" pos="0 0 0" />
                        <geom name="v_upper_arm_link" type="mesh" group="1" mesh="link2" pos="0.064 0 0" euler="0 -1.57 0" />
                        <geom name="v_upper_arm_link_1" type="mesh" group="1" mesh="shaft1" pos="-0.145 0 0" euler="0 -1.57 0" />    

                            <body name="forearm_link" pos="-0.55 0 0" euler="1.57 -1.57 0">
                                    <inertial pos="0.11993 0 0.0265" mass="2.275" fullinertia="0.0025 0.0551 0.0546 0 0.0034 0" />
                                    <joint class="arm1" name="arm:elbow_joint" pos="0 0 0" axis="0 0 1" />
                                    <geom name="v_forearm_link" type="mesh" group="1" mesh="link2" pos="0 0 0.032 " euler="3.14 0 0" />
                                    <geom name="v_forearm_link_1" type="mesh" group="1" mesh="shaft2" pos="-0.0906 0 -0.032" euler="0 1.57 0" />
                                    <body name="wrist_1_link" pos="-0.162 0 0.390 " euler="0 -1.5707963 -1.5707963">

                                    <inertial pos="0.0 0 0.0" mass="1" diaginertia="1 1 1" />
                                    <joint class="arm2" name="arm:wrist_1_joint" pos="0 -0.390 0" axis="0 0 1" />
                                    <geom name="v_wrist_1_link" type="mesh" group="1" mesh="link3" pos="0 -0.478 -0.025 " euler="-1.57 0 -1.57"/>
                                    <geom name="v_wrist_1_link_1" type="mesh" group="1" mesh="shaft2" pos="0.039 0 -0.025" euler="0 1.57 0"/>
                                        <body name="wrist_2_link" pos="0.160 0.370 0" euler="1.5707963 1.5707963 0">
                                            <inertial pos="0 0.0018 0.01634" mass="1" diaginertia="0.0012 0.0012 0.0009" />
                                            <joint class="arm2" name="arm:wrist_2_joint" pos="-0.370 0 0" axis="0 0 1" />
                                            <geom name="v_wrist_2_link" type="mesh" group="1" mesh="link4" pos="0 0 0" euler="0 0 0" />
                                            <geom name="v_wrist_2_link_1" type="mesh" group="1" mesh="shaft2" pos="0 0 -0.0385 " euler="0 0 0" />
                                            
                                            <body name="wrist_3_link" pos="0.305 0 -0.160">
                                                <inertial pos="0 0 -0.01159" mass="1" diaginertia="0.0000884489143 0.0000884489143 0.000138534912" />
                                                <joint class="arm2" name="arm:wrist_3_joint" pos="-0.305 0 0" axis="0 0 1" />
                                                <geom name="v_wrist_3_link" type="mesh" group="1" mesh="link5" pos="0 0 0" euler="-1.57 0 0" />
                                                <body name="endeffector_1" pos="0 0 0" euler="1.57 0 0 ">
                                                    <inertial pos="0 0 0" mass="1" diaginertia="0 0 0"/>
                                                    <geom name="ee_1" type="mesh" group="1" mesh="ee1" pos="0 0 0" euler="0 0 0"/>
                                                    <body name="endeffector_2" pos="0 0 0">
                                                        <inertial pos="0 0 0" mass="1" diaginertia="0 0 0"/>
                                                        <geom name="ee_2" type="mesh" group="1" mesh="ee2" pos="0 0 0" euler="0 -2.09439 0"/>
                                                    </body>
                                                </body>
                                            </body>
                                        </body>
                                    </body>
                                </body>
                            </body>                      
                        </body>
                    </body>
            </body>
        </body>

    </worldbody>

    <actuator>

        <general group="1" biasprm="0 0 -100" biastype="affine" ctrllimited="true" ctrlrange="-3.14 3.14" forcelimited="true" forcerange="-150 150" gainprm="100 0 0" joint="arm:shoulder_pan_joint" name="arm:shoulder_pan_T" />
        <general group="1" biasprm="0 0 -100" biastype="affine" ctrllimited="true" ctrlrange="-3.14 3.14" forcelimited="true" forcerange="-150 150" gainprm="100 0 0" joint="arm:shoulder_lift_joint" name="arm:shoulder_lift_T" />
        <general group="1" biasprm="0 0 -100" biastype="affine" ctrllimited="true" ctrlrange="-3.14 3.14" forcelimited="true" forcerange="-150 150" gainprm="100 0 0" joint="arm:elbow_joint" name="arm:elbow_T" />
        <general group="1" biasprm="0 0 -50" biastype="affine" ctrllimited="true" ctrlrange="-3.14 3.14" forcelimited="true" forcerange="-28 28" gainprm="50 0 0" joint="arm:wrist_1_joint" name="arm:wrist_1_T" />
        <general group="1" biasprm="0 0 -50" biastype="affine" ctrllimited="true" ctrlrange="-3.14 3.14" forcelimited="true" forcerange="-28 28" gainprm="50 0 0" joint="arm:wrist_2_joint" name="arm:wrist_2_T" />
        <general group="1" biasprm="0 0 -50" biastype="affine" ctrllimited="true" ctrlrange="-3.14 3.14" forcelimited="true" forcerange="-28 28" gainprm="50 0 0" joint="arm:wrist_3_joint" name="arm:wrist_3_T" />
    
    </actuator>

    <sensor>
        <actuatorfrc name="shoulder_pan_P_frc" actuator="arm:shoulder_pan_T" />
        <actuatorfrc name="shoulder_lift_P_frc" actuator="arm:shoulder_lift_T" />
        <actuatorfrc name="forearm_P_frc" actuator="arm:elbow_T" />
        <actuatorfrc name="wrist_1_P_frc" actuator="arm:wrist_1_T" />
        <actuatorfrc name="wrist_2_P_frc" actuator="arm:wrist_2_T" />
        <actuatorfrc name="wrist_3_P_frc" actuator="arm:wrist_3_T" />
    </sensor>

</mujoco>